<?xml version="1.0"?>
<robot name="physics">

  <link name="base">
    <visual>
      <geometry>
        <box size="0.2 0.2 0.2"/>
      </geometry>
      <origin xyz="0 0 0"/>
      <material name="white">
        <color rgba="1 1 1 1"/>
      </material>
    </visual>
    <collision>
      <geometry>
          <box size="0.5 0.5 0.2"/>
      </geometry>
      <origin xyz="0 0 0"/>
    </collision>
    <inertial>
      <mass value="0"/>
      <inertia ixx="1.0" ixy="0.0" ixz="0.0" iyy="1.0" iyz="0.0" izz="1.0"/>
    </inertial>
  </link>

  <link name="link1">
  <origin xyz="-0.5 0 0"/>
    <inertial>
      <origin xyz="0.5 0 0"/>
      <mass value="1"/>
      <inertia ixx="1e-5" ixy="0.0" ixz="0.0" iyy="1e-5" iyz="0.0" izz="1e-5"/>
    </inertial>

    <visual>
      <geometry>
        <box size="1.0 0.05 0.05"/>	
      </geometry>
      <origin rpy="0 0 0" xyz="0.5 0 0"/>
      <material name="blue">
        <color rgba="0 0 0.8 1"/>
      </material>
    </visual>
    
    <collision>
      <geometry>
        <box size="0 0 0"/>	
      </geometry>
      <origin rpy="0 0 0" xyz="0.5 0 0"/>
    </collision>

  </link>

  <joint name="base_to_link1" type="continuous">
    <axis xyz="0 0 1"/>
    <origin xyz="0.0 0.0 0.0" rpy="0.0 0.0 0.0"/>
    <parent link="base"/>
    <child link="link1"/>
  </joint>

  <link name="link2">
  <origin xyz="-0.5 0 0"/>
    <inertial>
      <origin xyz="1.0 0 0"/>
      <mass value="1"/>
      <inertia ixx="1e-5" ixy="0.0" ixz="0.0" iyy="1e-5" iyz="0.0" izz="1e-5"/>
    </inertial>

    <visual>
      <geometry>
        <box size="1.0 0.05 0.05"/>	
      </geometry>
      <origin rpy="0 0 0" xyz="0.5 0 0"/>
      <material name="red">
        <color rgba="0.8 0 0 1"/>
      </material>
    </visual>
    
    <collision>
      <geometry>
        <box size="0 0 0"/>	
      </geometry>
      <origin rpy="0 0 0" xyz="0.5 0 0"/>
    </collision>

  </link>

  <joint name="link1_to_link2" type="continuous">
    <axis xyz="0 0 1"/>
    <origin xyz="1.0 0.0 0.0" rpy="0.0 0.0 0.0"/>
    <parent link="link1"/>
    <child link="link2"/>
  </joint>

  <link name="ee">
    <inertial>
      <origin xyz="0.5 0 0"/>
      <mass value="0.5"/>
      <inertia ixx="1e-6" ixy="0.0" ixz="0.0" iyy="1e-6" iyz="0.0" izz="1e-6"/>
    </inertial>

    <visual>
      <geometry>
        <box size="0.5 0.025 0.025"/>	
      </geometry>
      <origin rpy="0 0 0" xyz="0.25 0 0"/>
      <material name="green">
        <color rgba="0 0.8 0 1"/>
      </material>
    </visual>
    
    <collision>
      <geometry>
        <box size="0 0 0"/>	
      </geometry>
      <origin rpy="0 0 0" xyz="0.0 0 0"/>
    </collision>

  </link>

  <joint name="link2_to_ee" type="fixed">
    <axis xyz="0 0 1"/>
    <origin xyz="1.0 0.0 0.0" rpy="0.0 0.0 0.4"/>
    <parent link="link2"/>
    <child link="ee"/>
  </joint>
  
</robot>
